<?xml version="1.0"?>
<robot name="BetterCylinderBot">

  <link name="base_link">
    <!-- Thin red base plate -->
    <visual>
      <origin xyz="0 0 0.025" rpy="0 0 0"/> <!-- 0.05 tall base -->
      <geometry>
        <box size="0.2 0.2 0.05"/>
      </geometry>
      <material name="red">
        <color rgba="1 0 0 1"/>
      </material>
    </visual>
  </link>

  <link name="link1">
    <!-- Main vertical body -->
    <visual>
      <origin xyz="0 0 0.25" rpy="0 0 0"/>
      <geometry>
        <cylinder radius="0.05" length="0.5"/>
      </geometry>
      <material name="green">
        <color rgba="0 0 1 1"/>
      </material>
    </visual>

    <!-- Joint barrel -->
    <visual>
      <origin xyz="0 0 0" rpy="0 0 0"/>
      <geometry>
        <cylinder radius="0.04" length="0.1"/>
      </geometry>
      <material name="gray">
        <color rgba="0.5 0.5 0.5 1"/>
      </material>
    </visual>
  </link>

  <link name="link2">
    <!-- Main vertical body -->
    <visual>
      <origin xyz="0 0 0.2" rpy="0 0 0"/>
      <geometry>
        <cylinder radius="0.04" length="0.4"/>
      </geometry>
      <material name="blue">
        <color rgba="0 1 0 1"/>
      </material>
    </visual>

    <!-- Joint barrel -->
    <visual>
      <origin xyz="0 0 0" rpy="1.5708 0 0"/>
      <geometry>
        <cylinder radius="0.04" length="0.1"/>
      </geometry>
      <material name="gray">
        <color rgba="0.5 0.5 0.5 1"/>
      </material>
    </visual>
  </link>

  <link name="link3">
    <!-- Main vertical body -->
    <visual>
      <origin xyz="0 0 0.15" rpy="0 0 0"/>
      <geometry>
        <cylinder radius="0.035" length="0.3"/>
      </geometry>
      <material name="orange">
        <color rgba="1 0.5 0 1"/>
      </material>
    </visual>

    <!-- Joint barrel -->
    <visual>
      <origin xyz="0 0 0" rpy="1.5708 0 0"/>
      <geometry>
        <cylinder radius="0.035" length="0.1"/>
      </geometry>
      <material name="gray">
        <color rgba="0.5 0.5 0.5 1"/>
      </material>
    </visual>
  </link>

  <!-- Joints -->
  <joint name="joint1" type="revolute">
    <parent link="base_link"/>
    <child link="link1"/>
    <origin xyz="0 0 0.05" rpy="0 0 0"/>
    <axis xyz="0 0 1"/>
    <limit lower="-3.14" upper="3.14" effort="10" velocity="1"/>
  </joint>

  <joint name="joint2" type="revolute">
    <parent link="link1"/>
    <child link="link2"/>
    <origin xyz="0 0 0.5" rpy="0 0 0"/>
    <axis xyz="0 1 0"/>
    <limit lower="-3.14" upper="3.14" effort="10" velocity="1"/>
  </joint>

  <joint name="joint3" type="revolute">
    <parent link="link2"/>
    <child link="link3"/>
    <origin xyz="0 0 0.4" rpy="0 0 0"/>
    <axis xyz="0 1 0"/>
    <limit lower="-3.14" upper="3.14" effort="10" velocity="1"/>
  </joint>

</robot>
